Workbook

Sheet Sheet1
A1: Sl No | B1: Student name | C1: mobile brand | D1: Number of languages known | E1: Device used to study | F1: Preffered time of study | G1: Gender | H1: social media often use | I1: state | J1: how much you wish to earn per month (numbers) | K1: caffeine intake (number of cups per day) | L1: mother tongue
A2: 1 | B2: AARYAN HARISH | C2: Apple | D2: 3
A3: 2 | B3: ABEL SAM DEVASIRVATHAM W | C3: Samsung | D3: 4 | E3: laptop | F3: anytime | G3: male | H3: instagram | I3: Karnataka | J3: infinite | K3: infinite | L3: tamil
A4: 3 | B4: ATHUL EMMANUEL STEPHEN | C4: Apple | D4: 5 | E4: laptop | F4: never night | G4: male | H4: instagram | I4: kerala | J4: 1e+21 | K4: 3 | L4: malalayam
A5: 4 | B5: IVAN JOHN | C5: Apple | D5: 4 | E5: Mobile | F5: Evening | G5: Male | H5: WhatsApp | I5: Karnataka | J5: 100 | K5: 0 | L5: Kannada
A6: 5 | B6: MEVIN VINCENT
A7: 6 | B7: SHANE CHRISTOPHER | C7: One plus | D7: 8 | E7: Tablet | F7: Morning
A8: 7 | B8: ISAAC KURIAN DAVID | C8: Motorola | D8: 5 | E8: laptop | F8: evening
A9: 8 | B9: LALITH CHOUDHARY | C9: xaomi | D9: 5 | E9: laptop | F9: evening
A10: 9 | B10: JASWANTH B | C10: vivo | D10: 5 | E10: pc | F10: evening | G10: male | H10: Whatsapp | I10: Karnataka | J10: 1000000 | K10: 10 | L10: Telugu
A11: 10 | B11: ALFONDER WARJRI | C11: Realme | D11: 3 | E11: laptop | F11: evening | G11: male | H11: Instagram | I11: Meghalaya | J11: 12351232 | K11: 0 | L11: Khasi
A12: 11 | B12: ARAV BHATIA | C12: Apple | D12: 3 | E12: laptop | F12: evening | G12: Male | H12: Instagram | I12: Punjab | J12: 100 | K12: 1 | L12: Hindi
A13: 12 | B13: HARIN S PRASAD | C13: One plus | D13: 5 | E13: PC | J13: 7 crore
A14: 13 | B14: KISHEN RAJ | C14: oppo | D14: 5 | E14: pc | F14: evening | G14: male | H14: instagram | I14: Karnataka | J14: 1000000000 | K14: 1 | L14: Tamil
A15: 14 | B15: SHREERAM K | C15: nothing | D15: 5 | E15: lap | F15: morning | G15: male | H15: instagram | I15: Karnataka | J15: 2 | K15: 0 | L15: malayalam
A16: 15 | B16: NAOKHOMBA KHANGEMBAM
A17: 16 | B17: DANIEL LUNGOUCHUON HAOKIP
A18: 17 | B18: JISS JAMES | C18: Nothing | D18: 3 | E18: Laptop | F18: Night | G18: Male | H18: Instagram | I18: Kerala | J18: 10000000 | K18: 4 | L18: Malayalam
A19: 18 | B19: THARANAA S J | C19: Nothing | D19: 2 | E19: laptop | F19: night | G19: female | H19: instagram | I19: tamil nadu | J19: 600000 | K19: 5 | L19: tamil
A20: 19 | B20: DEEBADHARSHAN S | C20: vivo | D20: 3 | E20: laptop | F20: night | G20: male | H20: instagram | I20: tamil nadu | J20: 700000 | K20: 3 | L20: tamil
A21: 20 | B21: SHIYAVUL IRFAN S | C21: vivio | D21: 3 | E21: laptop | F21: night | G21: male | H21: instagram | I21: tamil nadu | J21: 800000 | K21: 1 | L21: tamil
A22: 21 | B22: PRATYAKSH SHARMA
A23: 22 | B23: ANUSHKA BANDI | C23: apple | D23: 4 | E23: laptop | F23: never | G23: Female | H23: instagram | I23: karnataka | J23: 300000000 | K23: 1 | L23: telugu
A24: 23 | B24: AP ANN FIONA | C24: Nokia | D24: 5 | E24: laptop | F24: morning | G24: angel | H24: instagram | I24: karnataka | J24: 100000 | K24: 0 | L24: tamil
A25: 24 | B25: CEANA JASMINE C | C25: Poco | D25: 4 | E25: laptop | F25: Night | G25: female | H25: instagram | I25: karnataka | J25: 60000 | K25: 0 | L25: kannada
A26: 25 | B26: DEVALEKHA M | C26: one plus | D26: 4 | E26: laptop | F26: evening
A27: 26 | B27: H MOHAMMED ABHISHEIK | C27: Samsung | D27: 5 | E27: Laptop | F27: No study | G27: Male | H27: Instagram | I27: Tamil Nadu | J27: 676767 | K27: 3 | L27: Tamil
A28: 27 | B28: J MINTOPRABHU | C28: Apple | D28: 4 | E28: Laptop | F28: Evening | G28: Male | H28: Instagram | I28: Tamil Nadu | J28: 600000 | K28: 2 | L28: Tamil
A29: 28 | B29: KAVIN KIRTHICK R | C29: Samsung | D29: 2 | E29: Laptop | F29: Night | G29: Male | H29: Instagram | I29: Tamil Nadu | J29: 100000 | K29: none | L29: Tamil
A30: 29 | B30: KHUSHI N | C30: Samsung | D30: 4 | E30: Laptop | F30: Night | G30: female | H30: Instagram | I30: karnataka | J30: 50000 | K30: none
A31: 30 | B31: SHON VARGHESE | C31: Samsung | D31: 3 | E31: Laptop | F31: Day | G31: Male | H31: Instagram | I31: Kerala | J31: 100000 | K31: 1 | L31: malayalam
A32: 31 | B32: TARUN SAM EMMANUEL | C32: One Plus | D32: 3 | E32: Laptop | F32: Morning | G32: Male | H32: Instagram | I32: Karnataka | J32: 100000 | K32: 1 | L32: Tamil
A33: 32 | B33: CHAITHRA S | C33: Poco | D33: 3 | E33: Laptop | F33: Night | G33: Female | H33: Instagram | I33: Karnataka | J33: 50000 | K33: 2 | L33: Kannada
A34: 33 | B34: DEVIKA V | C34: Vivo | D34: 3 | E34: Laptop | F34: Night | G34: Female | H34: Instagram | I34: Karnataka | J34: 100000 | K34: 0 | L34: Tamil
A35: 34 | B35: SUNAINA PATRO | C35: One plus | D35: 4 | E35: Laptop | F35: Night | G35: Female | H35: Instagram | I35: Odisha | J35: 100000 | K35: 3 | L35: oriya | P35: \
A36: 35 | B36: ANAN MATHEW | C36: iqoo | D36: 5 | E36: Laptop | F36: Night | G36: Male | H36: Instagram | I36: Kerala | J36: 20000000 | K36: none | L36: Malayalam
A37: 36 | B37: JOSHUA JOHN V | C37: Infinix | D37: 4 | E37: Laptop
A38: 37 | B38: SHAIVI | C38: Apple | D38: 3 | E38: laptop | F38: never | G38: Female | H38: Instagram | I38: Karnataka | J38: 2000000 | K38: 0 | L38: kannada
A39: 38 | B39: KISHORE R | C39: iQOO | D39: 4 | E39: Mobile | F39: Evening | G39: Male | H39: INSTAGRAM | I39: Tamil Nadu | J39: 800000 | K39: 2 | L39: Tamil
A40: 39 | B40: ALBIN REGI JOHN | C40: Samsung | D40: 3 | E40: laptop | F40: evening | G40: MALE | H40: INSTAGRAM | I40: KERALA | J40: 100000000 | K40: 1 | L40: MALAYALAM
...

Sheet Sheet2
A1: =Sheet1!K1 -> caffeine intake (number of cups per day) | E1: =Sheet1!G1 -> Gender | N1: =Sheet1!I1 -> state | P1: States | Q1: num
A2: =Sheet1!K2 -> 0 | E2: =Sheet1!G2 -> 0 | F2: {=_xlfn.IFS(E2:E60="","N/A", LOWER(TRIM(E2:E60))="male","Male", LOWER(TRIM(E2:E60))="female","Female",TRUE,"N/A")} -> N/A | G2: male | H2: =COUNTIF(_xlfn.ANCHORARRAY(F2),"Male") -> 25 | N2: =Sheet1!I2 -> 0 | O2: {=_xlfn.IFS(N2:N60="","N/A", LOWER(TRIM(N2:N60))="karnataka","Karnataka", LOWER(TRIM(N2:N60))="kerala","Kerala", LOWER(TRIM(N2:N60))="tamil nadu","Tamil Nadu", LOWER(TRIM(N2:N60))="meghalaya","Meghalaya", LOWER(TRIM(N2:N60))="punjab","Punjab",TRUE,"N/A")} -> N/A | P2: Karnataka | Q2: =COUNTIF(_xlfn.ANCHORARRAY(O2),"Karnataka") -> 13
A3: 3 | E3: =Sheet1!G3 -> male | F3: Male | G3: female | H3: =COUNTIF(_xlfn.ANCHORARRAY(F2),"Female") -> 10 | N3: =Sheet1!I3 -> Karnataka | O3: Karnataka | P3: Kerala | Q3: =COUNTIF(_xlfn.ANCHORARRAY(O2),"Kerala") -> 9
A4: =Sheet1!K4 -> 3 | E4: =Sheet1!G4 -> male | F4: Male | G4: N/A | H4: =COUNTIF(_xlfn.ANCHORARRAY(F2),"N/A") -> 24 | N4: =Sheet1!I4 -> kerala | O4: Kerala | P4: Meghalaya | Q4: =COUNTIF(O:O,"Meghalaya") -> 1
A5: =Sheet1!K5 -> 0 | E5: =Sheet1!G5 -> Male | F5: Male | N5: =Sheet1!I5 -> Karnataka | O5: Karnataka | P5: Punjab | Q5: =COUNTIF(O:O,"Punjab") -> 1
A6: =Sheet1!K6 -> 0 | E6: =Sheet1!G6 -> 0 | F6: N/A | N6: =Sheet1!I6 -> 0 | O6: N/A | P6: Tamil nadu | Q6: =COUNTIF(O:O,"Tamil Nadu") -> 11
A7: =Sheet1!K7 -> 0 | E7: =Sheet1!G7 -> 0 | F7: N/A | N7: =Sheet1!I7 -> 0 | O7: N/A
A8: =Sheet1!K8 -> 0 | E8: =Sheet1!G8 -> 0 | F8: N/A | N8: =Sheet1!I8 -> 0 | O8: N/A
A9: =Sheet1!K9 -> 0 | E9: =Sheet1!G9 -> 0 | F9: N/A | N9: =Sheet1!I9 -> 0 | O9: N/A
A10: =Sheet1!K10 -> 10 | E10: =Sheet1!G10 -> male | F10: Male | N10: =Sheet1!I10 -> Karnataka | O10: Karnataka
A11: =Sheet1!K11 -> 0 | E11: =Sheet1!G11 -> male | F11: Male | N11: =Sheet1!I11 -> Meghalaya | O11: Meghalaya
A12: =Sheet1!K12 -> 1 | E12: =Sheet1!G12 -> Male | F12: Male | N12: =Sheet1!I12 -> Punjab | O12: Punjab
A13: =Sheet1!K13 -> 0 | E13: =Sheet1!G13 -> 0 | F13: N/A | N13: =Sheet1!I13 -> 0 | O13: N/A
A14: =Sheet1!K14 -> 1 | E14: =Sheet1!G14 -> male | F14: Male | N14: =Sheet1!I14 -> Karnataka | O14: Karnataka
A15: =Sheet1!K15 -> 0 | E15: =Sheet1!G15 -> male | F15: Male | N15: =Sheet1!I15 -> Karnataka | O15: Karnataka
A16: =Sheet1!K16 -> 0 | E16: =Sheet1!G16 -> 0 | F16: N/A | N16: =Sheet1!I16 -> 0 | O16: N/A
A17: =Sheet1!K17 -> 0 | E17: =Sheet1!G17 -> 0 | F17: N/A | N17: =Sheet1!I17 -> 0 | O17: N/A
A18: =Sheet1!K18 -> 4 | E18: =Sheet1!G18 -> Male | F18: Male | N18: =Sheet1!I18 -> Kerala | O18: Kerala
... A28: =Sheet1!K28 -> 2 | E28: =Sheet1!G28 -> Male | F28: Male | N28: =Sheet1!I28 -> Tamil Nadu | O28: Tamil Nadu
A29: 0 | E29: =Sheet1!G29 -> Male | F29: Male | N29: =Sheet1!I29 -> Tamil Nadu | O29: Tamil Nadu
A30: 0 | E30: =Sheet1!G30 -> female | F30: Female | N30: =Sheet1!I30 -> karnataka | O30: Karnataka
A31: =Sheet1!K31 -> 1 | E31: =Sheet1!G31 -> Male | F31: Male | N31: =Sheet1!I31 -> Kerala | O31: Kerala
A32: =Sheet1!K32 -> 1 | E32: =Sheet1!G32 -> Male | F32: Male | N32: =Sheet1!I32 -> Karnataka | O32: Karnataka
A33: =Sheet1!K33 -> 2 | E33: =Sheet1!G33 -> Female | F33: Female | N33: =Sheet1!I33 -> Karnataka | O33: Karnataka
A34: =Sheet1!K34 -> 0 | E34: =Sheet1!G34 -> Female | F34: Female | N34: =Sheet1!I34 -> Karnataka | O34: Karnataka
A35: =Sheet1!K35 -> 3 | E35: =Sheet1!G35 -> Female | F35: Female | N35: =Sheet1!I35 -> Odisha | O35: N/A
A36: 0 | E36: =Sheet1!G36 -> Male | F36: Male | N36: =Sheet1!I36 -> Kerala | O36: Kerala
A37: =Sheet1!K37 -> 0 | E37: =Sheet1!G37 -> 0 | F37: N/A | N37: =Sheet1!I37 -> 0 | O37: N/A
A38: =Sheet1!K38 -> 0 | E38: =Sheet1!G38 -> Female | F38: Female | N38: =Sheet1!I38 -> Karnataka | O38: Karnataka
A39: =Sheet1!K39 -> 2 | E39: =Sheet1!G39 -> Male | F39: Male | N39: =Sheet1!I39 -> Tamil Nadu | O39: Tamil Nadu
A40: =Sheet1!K40 -> 1 | E40: =Sheet1!G40 -> MALE | F40: Male | N40: =Sheet1!I40 -> KERALA | O40: Kerala
A41: =Sheet1!K41 -> 1 | E41: =Sheet1!G41 -> Female | F41: Female | N41: =Sheet1!I41 -> KERALA | O41: Kerala
A42: =Sheet1!K42 -> 0 | E42: =Sheet1!G42 -> 0 | F42: N/A | N42: =Sheet1!I42 -> 0 | O42: N/A
A43: =Sheet1!K43 -> 0 | E43: =Sheet1!G43 -> male | F43: Male | N43: =Sheet1!I43 -> KERALA | O43: Kerala
A44: =Sheet1!K44 -> 0 | E44: =Sheet1!G44 -> not male | F44: N/A | N44: =Sheet1!I44 -> 0 | O44: N/A
A45: 2 | E45: =Sheet1!G45 -> Male | F45: Male | N45: =Sheet1!I45 -> Tamil Nadu | O45: Tamil Nadu
A46: =Sheet1!K46 -> 2 | E46: =Sheet1!G46 -> Female | F46: Female | N46: =Sheet1!I46 -> Kerala | O46: Kerala
A47: =Sheet1!K47 -> 0 | E47: =Sheet1!G47 -> 0 | F47: N/A | N47: =Sheet1!I47 -> 0 | O47: N/A
A48: =Sheet1!K48 -> 0 | E48: =Sheet1!G48 -> 0 | F48: N/A | N48: =Sheet1!I48 -> 0 | O48: N/A
A49: =Sheet1!K49 -> 0 | E49: =Sheet1!G49 -> 0 | F49: N/A | N49: =Sheet1!I49 -> 0 | O49: N/A
...
